Workbook
Name sub_7637: 'Форма 807_коды'!#REF!
Name sub_7638: 'Форма 807_коды'!#REF!
Name sub_7639: 'Форма 807_коды'!#REF!
Name sub_7640: 'Форма 807_коды'!#REF!
Name sub_7641: 'Форма 807_коды'!#REF!
Name sub_7642: 'Форма 807_коды'!#REF!
Name sub_7643: 'Форма 807_коды'!#REF!
Name sub_7644: 'Форма 807_коды'!$A$14
Name sub_7645: 'Форма 807_коды'!$A$16
Name sub_7646: 'Форма 807_коды'!$A$17
Name sub_7647: 'Форма 807_коды'!$A$18
Name sub_7648: 'Форма 807_коды'!$A$19
Name sub_7649: 'Форма 807_коды'!$A$20
Name sub_7650: 'Форма 807_коды'!$A$21
Name sub_7651: 'Форма 807_коды'!$A$22
Name sub_7652: 'Форма 807_коды'!$A$23
Name sub_7653: 'Форма 807_коды'!$A$24
Name sub_7654: 'Форма 807_коды'!$A$25
Name sub_7655: 'Форма 807_коды'!$A$26
Name sub_7656: 'Форма 807_коды'!$A$27
Name sub_7657: 'Форма 807_коды'!$A$28
Name sub_7658: 'Форма 807_коды'!$A$29
Name sub_7659: 'Форма 807_коды'!$A$30
Name sub_7660: 'Форма 807_коды'!$A$31
Name sub_7661: 'Форма 807_коды'!$A$32
Name sub_7662: 'Форма 807_коды'!$A$33
Name sub_7663: 'Форма 807_коды'!$A$34
Name sub_7664: 'Форма 807_коды'!$A$35
Name sub_7665: 'Форма 807_коды'!$A$36
Name sub_7666: 'Форма 807_коды'!$A$37
Name sub_7667: 'Форма 807_коды'!$A$39
Name sub_7668: 'Форма 807_коды'!$A$40
Name sub_7669: 'Форма 807_коды'!$A$41
Name sub_7670: 'Форма 807_коды'!$A$42
Name sub_7671: 'Форма 807_коды'!$A$44
Name sub_7672: 'Форма 807_коды'!$A$45
Name sub_7673: 'Форма 807_коды'!$A$46
Name sub_7674: 'Форма 807_коды'!$A$47
Name sub_7675: 'Форма 807_коды'!$A$48
Name sub_7676: 'Форма 807_коды'!$A$49
Name sub_7677: 'Форма 807_коды'!$A$51
Name sub_7678: 'Форма 807_коды'!$A$52
Name sub_7679: 'Форма 807_коды'!$A$53
Name sub_7680: 'Форма 807_коды'!$A$54
Name sub_7681: 'Форма 807_коды'!$A$55
Name sub_7682: 'Форма 807_коды'!$A$57
Name sub_7683: 'Форма 807_коды'!$A$58
Name sub_7684: 'Форма 807_коды'!$A$59
Name sub_7685: 'Форма 807_коды'!$A$60
Name sub_7686: 'Форма 807_коды'!$A$61
Name sub_7687: 'Форма 807_коды'!$A$62
Name sub_7688: 'Форма 807_коды'!$A$63
Name Форма102_2016: #REF!
Name Форма102_2017: #REF!
Name Форма102_2018: #REF!
Name Форма102_2019: #REF!
Name Форма102_2020: #REF!

Sheet Форма 807_коды
A2: Разработочная таблица для составления Отчета о финансовых результатах (публикуемой формы)
A5: Номер | B5: Наименование статьи отчета о финансовых результатах (публикуемой формы) | C5: Символы отчетности по форме 0409102 и их расшифровки в соответствии с отчетностью по форме 04091101
A6: строки
A7: 1 | B7: 2 | C7: 3
A8: Раздел 1. Прибыли и убытки
A9: 1 | B9: Процентные доходы, всего (стр. 1.1 + стр. 1.2 + стр. 1.3 + стр. 1.4), в том числе:
A10: 44197 | B10: от размещения средств в кредитных организациях | C10: 11118 + 11119 + 11215 + 11216 + 11217 + 113 + 114 + 11803 +11807+ 12118 + 12119 + 12215 + 12216 + 12217 + 123 + 13118 + 13119 + 13215 + 13216 + 13217 + 133 + 134 + 13803 + 13807 + S27801/1.1 + S28401/1.1 - 33118 - 33119 - 33215 - 33216 - 33217 - 333 - 334 - 33803 - 33807 - 34118 - 34119 - 34215 - 34216 - 34217 - 34603 - 34607 - 35118 - 35119 - 35215 - 35216 - 35217 - 353 - 354 - 35803 - 35807 + S211/1.1
A11: 44228 | B11: от ссуд, предоставленных клиентам, не являющимся кредитными организациями | C11: 111 (кроме 11118, 11119) + 112 (кроме 11215, 11216, 11217) + 118 (кроме 11803, 11807) + 121 (кроме 12118, 12119) + 122 (кроме 12215, 12216, 12217) + 131 (кроме 13118, 13119) + 132 (кроме 13215, 13216, 13217) + 138 (кроме 13803, 13807) + 28401 + S278/1.2 - S28401/1.1 - 331 (кроме 33118, 33119) - 332 (кроме 33215, 33216, 33217) - 338 (кроме 33803, 33807) - 341 (кроме 34118, 34119) - 342 (кроме 34215, 34216, 34217) - 346 (кроме 34603, 34607) - 351 (кроме 35118, 35119) - 352 (кроме 35215, 35216, 35217) - 358 (кроме 35803, 35807) + S211/1.2
A12: 44256 | B12: от оказания услуг по финансовой аренде (лизингу) | C12: 28303
A13: 44287 | B13: от вложений в ценные бумаги | C13: 115 + 116 + 117 + 135 + 136 + 137 - 335 - 336 - 337 - 343 - 344 - 345 - 355 - 356 - 357
A14: 2 | B14: Процентные расходы, всего (стр. 2.1 + стр. 2.2 + стр. 2.3),
B15: в том числе:
A16: 44198 | B16: по привлеченным средствам кредитных организаций | C16: 311 (кроме 31104, 31105) + 31210 + 31211 + 31315 + 31316 + 31317 + 31415 + 31416 + 31417 + 319 + 321 (кроме 32104, 32105) + 32215 + 32216 + 32217 + 32315 + 32316 + 32317 + 361 (кроме 36104, 36105) + 36210 + 36211 + 36315 + 36316 + 36317 + 36415 + 36416 + 36417 + S47401/2.1 - 141 (кроме 14104, 14105) - 14210 - 14211 - 14315 - 14316 - 14317 - 14415 - 14416 - 14417
A17: 44229 | B17: по привлеченным средствам клиентов, не являющихся кредитными организациями | C17: 31104 + 31105 + 312 (кроме 31210, 31211) + 313 (кроме 31315, 31316, 31317) + 314 (кроме 31415, 31416, 31417) + 315 + 316 + 317 + 32104 + 32105 + 322 (кроме 32215, 32216, 32217) + 323 (кроме 32315, 32316, 32317) + 324 + 325 + 36104 + 36105 + 362 (кроме 36210, 36211) + 363 (кроме 36315, 36316, 36317) + 364 (кроме 36415, 36416, 36417) + 365 + 366 + 367 + 47401 - S47401/2.1 - 14104 - 14105 - 142 (кроме 14210, 14211) - 143 (кроме 14315, 14316, 14317) - 144 (кроме 14415, 14416, 14417) - 145 - 146 - 147
A18: 44257 | B18: по выпущенным ценным бумагам | C18: 318 + 326 + 368 - 148 - 161
A19: 3 | B19: Чистые процентные доходы (отрицательная процентная маржа) (стр. 1 - стр. 2)
A20: 4 | B20: Изменение резерва на возможные потери и оценочного резерва под ожидаемые кредитные убытки по ссудам, ссудной и приравненной к ней задолженности, средствам, размещенным на корреспондентских счетах, а также начисленным процентным доходам, всего, в том числе: | C20: 151 + 152 + 153 + 154 + 155 - S155/16 + 156 - S156/17 + 157 + 171 + 172 + 173 + 174 + 175 + 176 + 177 - S175/16 - S176/17 - 371 - 372 - 373 - 374 - 375 + S375/16 - 376 + S376/17 - 377 - 381 - 382 - 383 - 384 - 385 - 386 - 387 - S385/16 - S386/17 - S/18.1 + S/18.2 + S/4.5 - S/4.6
A21: 44200 | B21: изменение резерва на возможные потери и оценочного резерва под ожидаемые кредитные убытки по начисленным процентным доходам | C21: S/4.1 + S/4.2 - S/4.3 - S/4.4 + S282/4.1 - S473/4.1
A22: 5 | B22: Чистые процентные доходы (отрицательная процентная маржа) после создания резерва на возможные потери (стр. 3 + стр. 4)
A23: 6 | B23: Чистые доходы от операций с финансовыми активами, оцениваемыми по справедливой стоимости через прибыль или убыток | C23: 221 + 222 + 231 + 232 + 251 + 252 + 253 + 254 + 255 + 28104 + S256/6 - 421 - 422 - 431 - 432 - 451 - 452 - 453 - 454 - 455 - S456/6 - 47204
A24: 7 | B24: Чистые доходы от операций с финансовыми обязательствами, оцениваемыми по справедливой стоимости через прибыль или убыток | C24: 28101 + 28102 + 28103 - 47201 - 47202 - 47203
A25: 8 | B25: Чистые доходы от операций с ценными бумагами, оцениваемыми по справедливой стоимости через прочий совокупный доход | C25: 223 + 233 + S256/8 - 423 - 433 - S456/8
A26: 9 | B26: Чистые доходы от операций с ценными бумагами, оцениваемым по амортизированной стоимости | C26: 25611 + 25612 + 25613 + 25614 + 25615 + 224 - S256/6 - S256/8 - 424 - 45611 - 45612 - 45613 - 45614 - 45615 + S456/6 + S456/8
A27: 10 | B27: Чистые доходы от операций с иностранной валютой | C27: 25601 + 25602 + 25603 + 25604 + 25605 + 261 + 262- 45601 - 45602 - 45603 - 45604 - 45605 - 461 - 462
A28: 11 | B28: Чистые доходы от переоценки иностранной валюты | C28: 263 - 463
A29: 12 | B29: Чистые доходы от операций с драгоценными металлами | C29: 25616 + 25617 + 25618 + 25619 + 25620 + 264 + 265 - 45616 - 45617 - 45618 - 45619 - 45620 - 464 - 465
A30: 13 | B30: Доходы от участия в капитале других юридических лиц | C30: 235 + 236 + 237 + 238 + 239 - 435
A31: 14 | B31: Комиссионные доходы | C31: 271 + 272 + 273 + 274 + 275 + 276 + 279
A32: 15 | B32: Комиссионные расходы | C32: 471 (кроме 47108)
A33: 16 | B33: Изменение резерва на возможные потери и оценочного резерва под ожидаемые кредитные убытки по ценным бумагам, оцениваемые по справедливой стоимости через прочий совокупный доход | C33: S155/16 + S175/16 - S375/16 - S385/16
A34: 17 | B34: Изменение резерва на возможные потери и оценочного резерва под ожидаемые кредитные убытки по ценным бумагам, оцениваемым по амортизированной стоимости | C34: S156/17 + S176/17 - S376/17 - S386/17
... A36: 19 | B36: Прочие операционные доходы | C36: 211 + 212 + 213 + 214 + 215 + 216 + 225 + 226 + 241 + 242 + 243 + 244 + 245 + 246 + 247 + 248 + 249 + 25606 + 25607 + 25608 + 25609 + 25610 + 25621 + 25622 + 25623 + 25624 + 25625 + 25626 + 25627 + 277 + 278 + 283 (кроме 28303) + 28402 +285 + 286 + 287 + 288 + 291 + 292 + 294 - S27801/1.1 - S278/1.2 - S211/1.1 - S211/1.2
A37: 20 | B37: Чистые доходы (расходы)
B38: (стр. 5 + стр. 6 + стр. 7 + стр. 8 + стр. 9 + стр.10 + стр. 11 + стр.12 + стр. 13 + стр. 14 - стр. 15 + стр. 16 + стр. 17 + стр.18 + стр. 19)
A39: 21 | B39: Операционные расходы | C39: 411 + 412 + 413 + 414 + 415 + 416 + 425 + 426 + 441 + 442 + 443 + 444 + 445 + 446 + 447 + 448 + 449 + 45606 + 45607 + 45608 + 45609 + 45610 + 45621 + 45622 + 45623 + 45624 + 45625 + 45626 + 45627 + 47108 + 47402 + 475 + 476 + 477 + 47801 + 47802 + 47803 + 481 + 482 + 483 + 484 (кроме 48413) + 486
A40: 22 | B40: Прибыль (убыток) до налогообложения (стр. 20 - стр. 21)
A41: 23 | B41: Возмещение (расход) по налогам | C41: 48413 + 51101 + 51201 - 51202
A42: 24 | B42: Прибыль (убыток) от продолжающейся деятельности
B43: (стр. 22 - стр. 23 - стр. 25)
A44: 25 | B44: Прибыль (убыток) от прекращенной деятельности | C44: 28601 - 47601
...

Sheet Ф_102_2021
A1: Номер п/п | B1: Наименование статей | C1: Символы | D1: Рубли | E1: Ин.валюта | F1: ВСЕГО
B2: Часть 1. Процентные доходы, доходы от корректировок и от восстановления (уменьшения) резервов на возможные потери
B3: Раздел 1. Процентные доходы
B4: 1. По предоставленным кредитам и кредитам, права требования по которым приобретены:
A5: 1. | B5: Минфину России | C5: 11101 | D5: 0 | E5: 0 | F5: 0
A6: 2. | B6: финансовым органам субъектов Российской Федерации и органов местного самоуправления | C6: 11102 | D6: 0 | E6: 0 | F6: 0
A7: 3. | B7: государственным внебюджетным фондам Российской Федерации | C7: 11103 | D7: 0 | E7: 0 | F7: 0
A8: 4. | B8: внебюджетным фондам субъектов Российской Федерации и органов местного самоуправления | C8: 11104 | D8: 0 | E8: 0 | F8: 0
A9: 5. | B9: финансовым организациям, находящимся в федеральной собственности | C9: 11105 | D9: 56209 | E9: 0 | F9: 56209
A10: 6. | B10: коммерческим организациям, находящимся в федеральной собственности | C10: 11106 | D10: 427 | E10: 0 | F10: 427
A11: 7. | B11: некоммерческим организациям, находящимся в федеральной собственности | C11: 11107 | D11: 0 | E11: 0 | F11: 0
A12: 8. | B12: финансовым организациям, находящимся в государственной (кроме федеральной) собственности | C12: 11108 | D12: 3142 | E12: 0 | F12: 3142
A13: 9. | B13: коммерческим организациям, находящимся в государственной (кроме федеральной) собственности | C13: 11109 | D13: 118317 | E13: 0 | F13: 118317
A14: 10. | B14: некоммерческим организациям, находящимся в государственной (кроме федеральной) собственности | C14: 11110 | D14: 0 | E14: 0 | F14: 0
A15: 11. | B15: негосударственным финансовым организациям | C15: 11111 | D15: 570509 | E15: 0 | F15: 570509
A16: 12. | B16: негосударственным коммерческим организациям | C16: 11112 | D16: 6327635 | E16: 157628 | F16: 6485263
... A24: 20. | B24: иностранным государствам | C24: 11120 | D24: 0 | E24: 0 | F24: 0
B25: Итого по символам 11101 - 11120 | D25: 21436032 | E25: 1203708 | F25: 22639740
B26: 2. По прочим размещенным средствам, в том числе по прочим приобретенным правам требования:
A27: 1. | B27: в Минфине России | C27: 11201 | D27: 0 | E27: 0 | F27: 0
A28: 2. | B28: в финансовых органах субъектов Российской Федерации и органов местного самоуправления | C28: 11202 | D28: 0 | E28: 0 | F28: 0
A29: 3. | B29: в государственных внебюджетных фондах Российской Федерации | C29: 11203 | D29: 0 | E29: 0 | F29: 0
A30: 4. | B30: во внебюджетных фондах субъектов Российской Федерации и органов местного самоуправления | C30: 11204 | D30: 0 | E30: 0 | F30: 0
A31: 5. | B31: в финансовых организациях, находящихся в федеральной собственности | C31: 11205 | D31: 0 | E31: 0 | F31: 0
A32: 6. | B32: в коммерческих организациях, находящихся в федеральной собственности | C32: 11206 | D32: 0 | E32: 0 | F32: 0
A33: 7. | B33: в некоммерческих организациях, находящихся в федеральной собственности | C33: 11207 | D33: 0 | E33: 0 | F33: 0
A34: 8. | B34: в финансовых организациях, находящихся в государственной (кроме федеральной) собственности | C34: 11208 | D34: 0 | E34: 0 | F34: 0
A35: 9. | B35: в коммерческих организациях, находящихся в государственной (кроме федеральной) собственности | C35: 11209 | D35: 0 | E35: 0 | F35: 0
A36: 10. | B36: в некоммерческих организациях, находящихся в государственной (кроме федеральной) собственности | C36: 11210 | D36: 0 | E36: 0 | F36: 0
A37: 11. | B37: в негосударственных финансовых организациях | C37: 11211 | D37: 39320 | E37: 0 | F37: 39320
A38: 12. | B38: в негосударственных коммерческих организациях | C38: 11212 | D38: 245858 | E38: 0 | F38: 245858
... A46: 20. | B46: физическим лицам - нерезидентам | C46: 11220 | D46: 0 | E46: 0 | F46: 0
B47: Итого по символам 11201 - 11220 | D47: 2194181 | E47: 2086 | F47: 2196267
B48: 3. По денежным средствам на счетах:
A49: 1. | B49: в Банке России | C49: 11301 | D49: 85243 | E49: 0 | F49: 85243
A50: 2. | B50: в кредитных организациях | C50: 11302 | D50: 2 | E50: 188 | F50: 190
A51: 3. | B51: в банках-нерезидентах | C51: 11303 | D51: 0 | E51: 1510 | F51: 1510
B52: Итого по символам 11301 - 11303 | D52: 85245 | E52: 1698 | F52: 86943
B53: 4. По депозитам размещенным:
A54: 1. | B54: в Банке России | C54: 11401 | D54: 0 | E54: 0 | F54: 0
...

Sheet Ф_102_2020
A1: Номер п/п | B1: Наименование статей | C1: Символы | D1: Рубли | E1: Ин.валюта | F1: ВСЕГО
B2: Часть 1. Процентные доходы, доходы от корректировок и от восстановления (уменьшения) резервов на возможные потери
B3: Раздел 1. Процентные доходы
B4: 1. По предоставленным кредитам и кредитам, права требования по которым приобретены:
A5: 1. | B5: Минфину России | C5: 11101 | D5: 0 | E5: 0 | F5: 0
A6: 2. | B6: финансовым органам субъектов Российской Федерации и органов местного самоуправления | C6: 11102 | D6: 0 | E6: 0 | F6: 0
A7: 3. | B7: государственным внебюджетным фондам Российской Федерации | C7: 11103 | D7: 0 | E7: 0 | F7: 0
A8: 4. | B8: внебюджетным фондам субъектов Российской Федерации и органов местного самоуправления | C8: 11104 | D8: 0 | E8: 0 | F8: 0
A9: 5. | B9: финансовым организациям, находящимся в федеральной собственности | C9: 11105 | D9: 81951 | E9: 0 | F9: 81951
A10: 6. | B10: коммерческим организациям, находящимся в федеральной собственности | C10: 11106 | D10: 38509 | E10: 0 | F10: 38509
A11: 7. | B11: некоммерческим организациям, находящимся в федеральной собственности | C11: 11107 | D11: 0 | E11: 0 | F11: 0
A12: 8. | B12: финансовым организациям, находящимся в государственной (кроме федеральной) собственности | C12: 11108 | D12: 12167 | E12: 0 | F12: 12167
A13: 9. | B13: коммерческим организациям, находящимся в государственной (кроме федеральной) собственности | C13: 11109 | D13: 80366 | E13: 0 | F13: 80366
A14: 10. | B14: некоммерческим организациям, находящимся в государственной (кроме федеральной) собственности | C14: 11110 | D14: 0 | E14: 0 | F14: 0
A15: 11. | B15: негосударственным финансовым организациям | C15: 11111 | D15: 829435 | E15: 0 | F15: 829435
A16: 12. | B16: негосударственным коммерческим организациям | C16: 11112 | D16: 7637180 | E16: 17855 | F16: 7655035
... A24: 20. | B24: иностранным государствам | C24: 11120 | D24: 0 | E24: 0 | F24: 0
B25: Итого по символам 11101 - 11120 | D25: 20960733 | E25: 702697 | F25: 21663430
B26: 2. По прочим размещенным средствам, в том числе по прочим приобретенным правам требования:
A27: 1. | B27: в Минфине России | C27: 11201 | D27: 0 | E27: 0 | F27: 0
A28: 2. | B28: в финансовых органах субъектов Российской Федерации и органов местного самоуправления | C28: 11202 | D28: 0 | E28: 0 | F28: 0
A29: 3. | B29: в государственных внебюджетных фондах Российской Федерации | C29: 11203 | D29: 0 | E29: 0 | F29: 0
A30: 4. | B30: во внебюджетных фондах субъектов Российской Федерации и органов местного самоуправления | C30: 11204 | D30: 0 | E30: 0 | F30: 0
A31: 5. | B31: в финансовых организациях, находящихся в федеральной собственности | C31: 11205 | D31: 0 | E31: 0 | F31: 0
A32: 6. | B32: в коммерческих организациях, находящихся в федеральной собственности | C32: 11206 | D32: 0 | E32: 0 | F32: 0
A33: 7. | B33: в некоммерческих организациях, находящихся в федеральной собственности | C33: 11207 | D33: 0 | E33: 0 | F33: 0
A34: 8. | B34: в финансовых организациях, находящихся в государственной (кроме федеральной) собственности | C34: 11208 | D34: 0 | E34: 0 | F34: 0
A35: 9. | B35: в коммерческих организациях, находящихся в государственной (кроме федеральной) собственности | C35: 11209 | D35: 0 | E35: 0 | F35: 0
A36: 10. | B36: в некоммерческих организациях, находящихся в государственной (кроме федеральной) собственности | C36: 11210 | D36: 0 | E36: 0 | F36: 0
A37: 11. | B37: в негосударственных финансовых организациях | C37: 11211 | D37: 440391 | E37: 13623 | F37: 454014
A38: 12. | B38: в негосударственных коммерческих организациях | C38: 11212 | D38: 182605 | E38: 0 | F38: 182605
... A46: 20. | B46: физическим лицам - нерезидентам | C46: 11220 | D46: 0 | E46: 0 | F46: 0
B47: Итого по символам 11201 - 11220 | D47: 2363150 | E47: 18797 | F47: 2381947
B48: 3. По денежным средствам на счетах:
A49: 1. | B49: в Банке России | C49: 11301 | D49: 673154 | E49: 0 | F49: 673154
A50: 2. | B50: в кредитных организациях | C50: 11302 | D50: 5 | E50: 120 | F50: 125
A51: 3. | B51: в банках-нерезидентах | C51: 11303 | D51: 0 | E51: 1920 | F51: 1920
B52: Итого по символам 11301 - 11303 | D52: 673159 | E52: 2040 | F52: 675199
B53: 4. По депозитам размещенным:
A54: 1. | B54: в Банке России | C54: 11401 | D54: 0 | E54: 0 | F54: 0
...

Sheet Ф_102_2019
A1: Номер п/п | B1: Наименование статей | C1: Символы | D1: Рубли | E1: Ин.валюта | F1: ВСЕГО
B2: Часть 1. Процентные доходы, доходы от корректировок и от восстановления (уменьшения) резервов на возможные потери
B3: Раздел 1. Процентные доходы
B4: 1. По предоставленным кредитам и кредитам, права требования по которым приобретены:
A5: 1. | B5: Минфину России | C5: 11101 | D5: 0 | E5: 0 | F5: 0
A6: 2. | B6: финансовым органам субъектов Российской Федерации и органов местного самоуправления | C6: 11102 | D6: 2669 | E6: 0 | F6: 2669
A7: 3. | B7: государственным внебюджетным фондам Российской Федерации | C7: 11103 | D7: 0 | E7: 0 | F7: 0
A8: 4. | B8: внебюджетным фондам субъектов Российской Федерации и органов местного самоуправления | C8: 11104 | D8: 0 | E8: 0 | F8: 0
A9: 5. | B9: финансовым организациям, находящимся в федеральной собственности | C9: 11105 | D9: 107800 | E9: 0 | F9: 107800
A10: 6. | B10: коммерческим организациям, находящимся в федеральной собственности | C10: 11106 | D10: 17462 | E10: 0 | F10: 17462
A11: 7. | B11: некоммерческим организациям, находящимся в федеральной собственности | C11: 11107 | D11: 0 | E11: 0 | F11: 0
A12: 8. | B12: финансовым организациям, находящимся в государственной (кроме федеральной) собственности | C12: 11108 | D12: 0 | E12: 0 | F12: 0
A13: 9. | B13: коммерческим организациям, находящимся в государственной (кроме федеральной) собственности | C13: 11109 | D13: 50561 | E13: 0 | F13: 50561
A14: 10. | B14: некоммерческим организациям, находящимся в государственной (кроме федеральной) собственности | C14: 11110 | D14: 269597 | E14: 0 | F14: 269597
A15: 11. | B15: негосударственным финансовым организациям | C15: 11111 | D15: 854130 | E15: 22240 | F15: 876370
A16: 12. | B16: негосударственным коммерческим организациям | C16: 11112 | D16: 8797995 | E16: 178885 | F16: 8976880
... A24: 20. | B24: иностранным государствам | C24: 11120 | D24: 0 | E24: 0 | F24: 0
B25: Итого по символам 11101 - 11120 | D25: 22622853 | E25: 919307 | F25: 23542160
B26: 2. По прочим размещенным средствам, в том числе по прочим приобретенным правам требования:
A27: 1. | B27: в Минфине России | C27: 11201 | D27: 0 | E27: 0 | F27: 0
A28: 2. | B28: в финансовых органах субъектов Российской Федерации и органов местного самоуправления | C28: 11202 | D28: 0 | E28: 0 | F28: 0
A29: 3. | B29: в государственных внебюджетных фондах Российской Федерации | C29: 11203 | D29: 0 | E29: 0 | F29: 0
A30: 4. | B30: во внебюджетных фондах субъектов Российской Федерации и органов местного самоуправления | C30: 11204 | D30: 0 | E30: 0 | F30: 0
A31: 5. | B31: в финансовых организациях, находящихся в федеральной собственности | C31: 11205 | D31: 0 | E31: 0 | F31: 0
A32: 6. | B32: в коммерческих организациях, находящихся в федеральной собственности | C32: 11206 | D32: 0 | E32: 0 | F32: 0
A33: 7. | B33: в некоммерческих организациях, находящихся в федеральной собственности | C33: 11207 | D33: 0 | E33: 0 | F33: 0
A34: 8. | B34: в финансовых организациях, находящихся в государственной (кроме федеральной) собственности | C34: 11208 | D34: 0 | E34: 0 | F34: 0
A35: 9. | B35: в коммерческих организациях, находящихся в государственной (кроме федеральной) собственности | C35: 11209 | D35: 0 | E35: 0 | F35: 0
A36: 10. | B36: в некоммерческих организациях, находящихся в государственной (кроме федеральной) собственности | C36: 11210 | D36: 0 | E36: 0 | F36: 0
A37: 11. | B37: в негосударственных финансовых организациях | C37: 11211 | D37: 488327 | E37: 0 | F37: 488327
A38: 12. | B38: в негосударственных коммерческих организациях | C38: 11212 | D38: 155783 | E38: 0 | F38: 155783
... A46: 20. | B46: физическим лицам - нерезидентам | C46: 11220 | D46: 0 | E46: 0 | F46: 0
B47: Итого по символам 11201 - 11220 | D47: 3172713 | E47: 243 | F47: 3172956
B48: 3. По денежным средствам на счетах:
A49: 1. | B49: в Банке России | C49: 11301 | D49: 2679550 | E49: 0 | F49: 2679550
A50: 2. | B50: в кредитных организациях | C50: 11302 | D50: 6 | E50: 144 | F50: 150
A51: 3. | B51: в банках-нерезидентах | C51: 11303 | D51: 0 | E51: 2892 | F51: 2892
B52: Итого по символам 11301 - 11303 | D52: 2679556 | E52: 3036 | F52: 2682592
B53: 4. По депозитам размещенным:
A54: 1. | B54: в Банке России | C54: 11401 | D54: 0 | E54: 0 | F54: 0
...

Sheet Ф_102_2018
A1: Номер п/п | B1: Наименование статей | C1: Символы | D1: Рубли | E1: Ин.валюта | F1: ВСЕГО
B2: Часть 1. Процентные доходы, доходы от корректировок и от восстановления (уменьшения) резервов на возможные потери
B3: Раздел 1. Процентные доходы
B4: 1. По предоставленным кредитам и кредитам, права требования по которым приобретены:
A5: 1. | B5: Минфину России | C5: 11101 | D5: 0 | E5: 0 | F5: 0
A6: 2. | B6: финансовым органам субъектов Российской Федерации и органов местного самоуправления | C6: 11102 | D6: 0 | E6: 0 | F6: 0
A7: 3. | B7: государственным внебюджетным фондам Российской Федерации | C7: 11103 | D7: 0 | E7: 0 | F7: 0
A8: 4. | B8: внебюджетным фондам субъектов Российской Федерации и органов местного самоуправления | C8: 11104 | D8: 0 | E8: 0 | F8: 0
A9: 5. | B9: финансовым организациям, находящимся в федеральной собственности | C9: 11105 | D9: 75608 | E9: 0 | F9: 75608
A10: 6. | B10: коммерческим организациям, находящимся в федеральной собственности | C10: 11106 | D10: 0 | E10: 0 | F10: 0
A11: 7. | B11: некоммерческим организациям, находящимся в федеральной собственности | C11: 11107 | D11: 0 | E11: 0 | F11: 0
A12: 8. | B12: финансовым организациям, находящимся в государственной (кроме федеральной) собственности | C12: 11108 | D12: 0 | E12: 0 | F12: 0
A13: 9. | B13: коммерческим организациям, находящимся в государственной (кроме федеральной) собственности | C13: 11109 | D13: 8179 | E13: 0 | F13: 8179
A14: 10. | B14: некоммерческим организациям, находящимся в государственной (кроме федеральной) собственности | C14: 11110 | D14: 542172 | E14: 0 | F14: 542172
A15: 11. | B15: негосударственным финансовым организациям | C15: 11111 | D15: 965109 | E15: 27696 | F15: 992805
A16: 12. | B16: негосударственным коммерческим организациям | C16: 11112 | D16: 9017855 | E16: 130545 | F16: 9148400
... A24: 20. | B24: иностранным государствам | C24: 11120 | D24: 0 | E24: 0 | F24: 0
B25: Итого по символам 11101 - 11120 | D25: 20020535 | E25: 185959 | F25: 20206494
B26: 2. По прочим размещенным средствам, в том числе по прочим приобретенным правам требования:
A27: 1. | B27: в Минфине России | C27: 11201 | D27: 0 | E27: 0 | F27: 0
A28: 2. | B28: в финансовых органах субъектов Российской Федерации и органов местного самоуправления | C28: 11202 | D28: 0 | E28: 0 | F28: 0
A29: 3. | B29: в государственных внебюджетных фондах Российской Федерации | C29: 11203 | D29: 0 | E29: 0 | F29: 0
A30: 4. | B30: во внебюджетных фондах субъектов Российской Федерации и органов местного самоуправления | C30: 11204 | D30: 0 | E30: 0 | F30: 0
A31: 5. | B31: в финансовых организациях, находящихся в федеральной собственности | C31: 11205 | D31: 0 | E31: 0 | F31: 0
A32: 6. | B32: в коммерческих организациях, находящихся в федеральной собственности | C32: 11206 | D32: 0 | E32: 0 | F32: 0
A33: 7. | B33: в некоммерческих организациях, находящихся в федеральной собственности | C33: 11207 | D33: 0 | E33: 0 | F33: 0
A34: 8. | B34: в финансовых организациях, находящихся в государственной (кроме федеральной) собственности | C34: 11208 | D34: 0 | E34: 0 | F34: 0
A35: 9. | B35: в коммерческих организациях, находящихся в государственной (кроме федеральной) собственности | C35: 11209 | D35: 0 | E35: 0 | F35: 0
A36: 10. | B36: в некоммерческих организациях, находящихся в государственной (кроме федеральной) собственности | C36: 11210 | D36: 0 | E36: 0 | F36: 0
A37: 11. | B37: в негосударственных финансовых организациях | C37: 11211 | D37: 69025 | E37: 0 | F37: 69025
A38: 12. | B38: в негосударственных коммерческих организациях | C38: 11212 | D38: 218153 | E38: 0 | F38: 218153
... A46: 20. | B46: физическим лицам - нерезидентам | C46: 11220 | D46: 0 | E46: 0 | F46: 0
B47: Итого по символам 11201 - 11220 | D47: 1781816 | E47: 153695 | F47: 1935511
B48: 3. По денежным средствам на счетах:
A49: 1. | B49: в Банке России | C49: 11301 | D49: 2607824 | E49: 0 | F49: 2607824
A50: 2. | B50: в кредитных организациях | C50: 11302 | D50: 5 | E50: 111 | F50: 116
A51: 3. | B51: в банках-нерезидентах | C51: 11303 | D51: 0 | E51: 2630 | F51: 2630
B52: Итого по символам 11301 - 11303 | D52: 2607829 | E52: 2741 | F52: 2610570
B53: 4. По депозитам размещенным:
A54: 1. | B54: в Банке России | C54: 11401 | D54: 0 | E54: 0 | F54: 0
...

Sheet Ф_102_2017
A1: Номер п/п | B1: Наименование статей | C1: Символы | D1: Рубли | E1: Ин.валюта | F1: ВСЕГО
B2: Часть 1. Процентные доходы, доходы от корректировок и от восстановления (уменьшения) резервов на возможные потери
B3: Раздел 1. Процентные доходы
B4: 1. По предоставленным кредитам и кредитам, права требования по которым приобретены:
A5: 1. | B5: Минфину России | C5: 11101 | D5: 0 | E5: 0 | F5: 0
A6: 2. | B6: финансовым органам субъектов Российской Федерации и органов местного самоуправления | C6: 11102 | D6: 0 | E6: 0 | F6: 0
A7: 3. | B7: государственным внебюджетным фондам Российской Федерации | C7: 11103 | D7: 0 | E7: 0 | F7: 0
A8: 4. | B8: внебюджетным фондам субъектов Российской Федерации и органов местного самоуправления | C8: 11104 | D8: 0 | E8: 0 | F8: 0
A9: 5. | B9: финансовым организациям, находящимся в федеральной собственности | C9: 11105 | D9: 0 | E9: 0 | F9: 0
A10: 6. | B10: коммерческим организациям, находящимся в федеральной собственности | C10: 11106 | D10: 0 | E10: 0 | F10: 0
A11: 7. | B11: некоммерческим организациям, находящимся в федеральной собственности | C11: 11107 | D11: 48 | E11: 0 | F11: 48
A12: 8. | B12: финансовым организациям, находящимся в государственной (кроме федеральной) собственности | C12: 11108 | D12: 68492 | E12: 0 | F12: 68492
A13: 9. | B13: коммерческим организациям, находящимся в государственной (кроме федеральной) собственности | C13: 11109 | D13: 4388 | E13: 0 | F13: 4388
A14: 10. | B14: некоммерческим организациям, находящимся в государственной (кроме федеральной) собственности | C14: 11110 | D14: 900000 | E14: 0 | F14: 900000
A15: 11. | B15: негосударственным финансовым организациям | C15: 11111 | D15: 1035271 | E15: 34675 | F15: 1069946
A16: 12. | B16: негосударственным коммерческим организациям | C16: 11112 | D16: 12067177 | E16: 45307 | F16: 12112484
... A24: 20. | B24: иностранным государствам | C24: 11120 | D24: 0 | E24: 0 | F24: 0
B25: Итого по символам 11101 - 11120 | D25: 23159466 | E25: 82863 | F25: 23242329
B26: 2. По прочим размещенным средствам, в том числе по прочим приобретенным правам
A27: 1. | B27: в Минфине России | C27: 11201 | D27: 0 | E27: 0 | F27: 0
A28: 2. | B28: в финансовых органах субъектов Российской Федерации и органов местного самоуправления | C28: 11202 | D28: 0 | E28: 0 | F28: 0
A29: 3. | B29: в государственных внебюджетных фондах Российской Федерации | C29: 11203 | D29: 0 | E29: 0 | F29: 0
A30: 4. | B30: во внебюджетных фондах субъектов Российской Федерации и органов местного самоуправления | C30: 11204 | D30: 0 | E30: 0 | F30: 0
A31: 5. | B31: в финансовых организациях, находящихся в федеральной собственности | C31: 11205 | D31: 0 | E31: 0 | F31: 0
A32: 6. | B32: в коммерческих организациях, находящихся в федеральной собственности | C32: 11206 | D32: 0 | E32: 0 | F32: 0
A33: 7. | B33: в некоммерческих организациях, находящихся в федеральной собственности | C33: 11207 | D33: 0 | E33: 0 | F33: 0
A34: 8. | B34: в финансовых организациях, находящихся в государственной (кроме федеральной) собственности | C34: 11208 | D34: 0 | E34: 0 | F34: 0
A35: 9. | B35: в коммерческих организациях, находящихся в государственной (кроме федеральной) собственности | C35: 11209 | D35: 0 | E35: 0 | F35: 0
A36: 10. | B36: в некоммерческих организациях, находящихся в государственной (кроме федеральной) собственности | C36: 11210 | D36: 0 | E36: 0 | F36: 0
A37: 11. | B37: в негосударственных финансовых организациях | C37: 11211 | D37: 17 | E37: 0 | F37: 17
A38: 12. | B38: в негосударственных коммерческих организациях | C38: 11212 | D38: 121218 | E38: 0 | F38: 121218
... A46: 20. | B46: физическим лицам - нерезидентам | C46: 11220 | D46: 0 | E46: 0 | F46: 0
B47: Итого по символам 11201 - 11220 | D47: 1271542 | E47: 116533 | F47: 1388075
B48: 3. По денежным средствам на счетах:
A49: 1. | B49: в Банке России | C49: 11301 | D49: 507630 | E49: 0 | F49: 507630
A50: 2. | B50: в кредитных организациях | C50: 11302 | D50: 121 | E50: 74 | F50: 195
A51: 3. | B51: в банках-нерезидентах | C51: 11303 | D51: 0 | E51: 2103 | F51: 2103
B52: Итого по символам 11301 - 11303 | D52: 507751 | E52: 2177 | F52: 509928
B53: 4. По депозитам размещенным:
A54: 1. | B54: в Банке России | C54: 11401 | D54: 0 | E54: 0 | F54: 0
...

Sheet Ф_102_2016
A1: Номер п/п | B1: Наименование статей | C1: Символы | D1: Рубли | E1: Ин.валюта | F1: ВСЕГО
B2: Часть 1. Процентные доходы, доходы от корректировок и от восстановления (уменьшения) резервов на возможные потери
B3: Раздел 1. Процентные доходы
B4: 1. По предоставленным кредитам и кредитам, права требования по которым приобретены:
A5: 1. | B5: Минфину России | C5: 11101 | D5: 0 | E5: 0 | F5: 0
A6: 2. | B6: финансовым органам субъектов Российской Федерации и органов местного самоуправления | C6: 11102 | D6: 0 | E6: 0 | F6: 0
A7: 3. | B7: государственным внебюджетным фондам Российской Федерации | C7: 11103 | D7: 0 | E7: 0 | F7: 0
A8: 4. | B8: внебюджетным фондам субъектов Российской Федерации и органов местного самоуправления | C8: 11104 | D8: 0 | E8: 0 | F8: 0
A9: 5. | B9: финансовым организациям, находящимся в федеральной собственности | C9: 11105 | D9: 0 | E9: 0 | F9: 0
A10: 6. | B10: коммерческим организациям, находящимся в федеральной собственности | C10: 11106 | D10: 0 | E10: 0 | F10: 0
A11: 7. | B11: некоммерческим организациям, находящимся в федеральной собственности | C11: 11107 | D11: 660 | E11: 0 | F11: 660
A12: 8. | B12: финансовым организациям, находящимся в государственной (кроме федеральной) собственности | C12: 11108 | D12: 0 | E12: 0 | F12: 0
A13: 9. | B13: коммерческим организациям, находящимся в государственной (кроме федеральной) собственности | C13: 11109 | D13: 8358 | E13: 0 | F13: 8358
A14: 10. | B14: некоммерческим организациям, находящимся в государственной (кроме федеральной) собственности | C14: 11110 | D14: 1107650 | E14: 0 | F14: 1107650
A15: 11. | B15: негосударственным финансовым организациям | C15: 11111 | D15: 1523303 | E15: 3617 | F15: 1526920
A16: 12. | B16: негосударственным коммерческим организациям | C16: 11112 | D16: 18211937 | E16: 1093684 | F16: 19305621
... A24: 20. | B24: иностранным государствам | C24: 11120 | D24: 0 | E24: 0 | F24: 0
B25: Итого по символам 11101 - 11120 | D25: 28741417 | E25: 1112886 | F25: 29854303
B26: 2. По прочим размещенным средствам, в том числе по прочим приобретенным правам
A27: 1. | B27: в Минфине России | C27: 11201 | D27: 0 | E27: 0 | F27: 0
A28: 2. | B28: в финансовых органах субъектов Российской Федерации и органов местного самоуправления | C28: 11202 | D28: 0 | E28: 0 | F28: 0
A29: 3. | B29: в государственных внебюджетных фондах Российской Федерации | C29: 11203 | D29: 0 | E29: 0 | F29: 0
A30: 4. | B30: во внебюджетных фондах субъектов Российской Федерации и органов местного самоуправления | C30: 11204 | D30: 0 | E30: 0 | F30: 0
A31: 5. | B31: в финансовых организациях, находящихся в федеральной собственности | C31: 11205 | D31: 0 | E31: 0 | F31: 0
A32: 6. | B32: в коммерческих организациях, находящихся в федеральной собственности | C32: 11206 | D32: 0 | E32: 0 | F32: 0
A33: 7. | B33: в некоммерческих организациях, находящихся в федеральной собственности | C33: 11207 | D33: 0 | E33: 0 | F33: 0
A34: 8. | B34: в финансовых организациях, находящихся в государственной (кроме федеральной) собственности | C34: 11208 | D34: 0 | E34: 0 | F34: 0
A35: 9. | B35: в коммерческих организациях, находящихся в государственной (кроме федеральной) собственности | C35: 11209 | D35: 0 | E35: 0 | F35: 0
A36: 10. | B36: в некоммерческих организациях, находящихся в государственной (кроме федеральной) собственности | C36: 11210 | D36: 72302 | E36: 0 | F36: 72302
A37: 11. | B37: в негосударственных финансовых организациях | C37: 11211 | D37: 61492 | E37: 2181 | F37: 63673
A38: 12. | B38: в негосударственных коммерческих организациях | C38: 11212 | D38: 752699 | E38: 375875 | F38: 1128574
... A46: 20. | B46: физическим лицам - нерезидентам | C46: 11220 | D46: 0 | E46: 0 | F46: 0
B47: Итого по символам 11201 - 11220 | D47: 1760029 | E47: 722849 | F47: 2482878
B48: 3. По денежным средствам на счетах:
A49: 1. | B49: в Банке России | C49: 11301 | D49: 1133 | E49: 0 | F49: 1133
A50: 2. | B50: в кредитных организациях | C50: 11302 | D50: 422 | E50: 217 | F50: 639
A51: 3. | B51: в банках-нерезидентах | C51: 11303 | D51: 0 | E51: 4532 | F51: 4532
B52: Итого по символам 11301 - 11303 | D52: 1555 | E52: 4749 | F52: 6304
B53: 4. По депозитам размещенным:
A54: 1. | B54: в Банке России | C54: 11401 | D54: 0 | E54: 0 | F54: 0
...

Sheet МСФО_ввод
D2: Наименование банка | E2: ОАО "Банк Москвы"
D3: Стандарт составления отчетности | E3: МСФО
D4: Тип отчетности | E4: Консолидированная
D6: Отчет о финансовом положении | E6: На 31.12'
D7: млрд руб. | E7: 2009 | F7: 2010 | G7: 2011 | H7: 2012 | I7: 2013 | J7: 2014 | K7: 2015
D8: Активы
D9: Денежные средства и краткосрочные активы | E9: 75.164 | F9: 71.53 | G9: 62.851 | H9: 70.22 | I9: 89.767 | J9: 79.3 | K9: 77.6
D10: Обязательные резервы в центральных банках | E10: 4.748 | F10: 5.588 | G10: 9.753 | H10: 7.006 | I10: 6.669 | J10: 7.9 | K10: 5.2
D11: Финансовые активы, предназначенные для торговли | E11: 90.441 | F11: 86.609 | G11: 33.434 | H11: 32.851 | I11: 58.606 | J11: 25.6 | K11: 14.1
D12: Финансовые активы, заложенные по договорам "репо" | E12: 4.936 | F12: 38.175 | G12: 185.247 | H12: 263.098 | I12: 273.145 | J12: 281.5 | K12: 126.7
D13: Средства в банках | E13: 50.703 | F13: 79.485 | G13: 158.825 | H13: 167.503 | I13: 162.86 | J13: 508.9 | K13: 177.2
D14: Кредиты и авансы клиентам | E14: 558.165 | F14: 505.72 | G14: 533.735 | H14: 649.994 | I14: 909.061 | J14: 1096.3 | K14: 954.4
D15: Финансовые активы, имеющиеся в наличии для продажи | E15: 15.032 | F15: 14.723 | G15: 18.258 | H15: 25.792 | I15: 28.828 | J15: 10.8 | K15: 25.8
D16: Инвестиционные ценные бумаги, удерживаемые для погашения | E16: 0.265 | F16: 0.418 | G16: 0.324 | H16: 0.132 | I16: 0.004 | J16: 0 | K16: 16
D17: Инвестиции в ассоциированные компании | E17: 3.82 | F17: 3.247 | G17: 3.121 | H17: 0.756 | I17: 1.008 | J17: 1.8 | K17: 2.4
D18: Основные средства и нематериальные активы | E18: 17.284 | F18: 15.965 | G18: 20.457 | H18: 33.881 | I18: 40.747 | J18: 66.4 | K18: 52.3
D19: Инвестиционная недвижимость | E19: 0 | F19: 3.638 | G19: 3.785 | H19: 5.076 | I19: 14.034 | J19: 19.1 | K19: 28
D20: Активы, предназначенные для продажи | E20: 0 | F20: 0 | G20: 10.33 | H20: 15.234 | I20: 24.412 | J20: 0.3 | K20: 8.4
... D23: Прочие активы | E23: 3.822 | F23: 5.842 | G23: 5.076 | H23: 9.457 | I23: 12.102 | J23: 13.2 | K23: 6.4
D24: Итого активы | E24: =SUM(E9:E23) -> 825.206 | F24: =SUM(F9:F23) -> 849.476 | G24: =SUM(G9:G23) -> 1060.002 | H24: =SUM(H9:H23) -> 1293.015 | I24: =SUM(I9:I23) -> 1628.653 | J24: =SUM(J9:J23) -> 2129.1 | K24: =SUM(K9:K23) -> 1509.2
D25: Обязательства
D26: Средства банков | E26: 137.76 | F26: 145.198 | G26: 44.001 | H26: 101.678 | I26: 205.027 | J26: 543.7 | K26: 68.9
D27: Средства, привлеченные от ЦБ РФ | E27: 73.845 | F27: 0 | G27: 159.745 | H27: 264.685 | I27: 272.445 | J27: 406.1 | K27: 211.1
D28: Финансовые обязательства, предназначенные для торговли | G28: 3.156 | H28: 2.528 | I28: 1.697 | J28: 0.3 | K28: 0
D29: Средства клиентов | E29: 428.028 | F29: 543.14 | G29: 418.688 | H29: 464.022 | I29: 615.622 | J29: 631.8 | K29: 686.9
D30: Выпущенные долговые ценные бумаги | E30: 56.862 | F30: 81.103 | G30: 73.616 | H30: 66.971 | I30: 69.963 | J30: 101.5 | K30: 52.3
D31: Средства, привлеченные от ГК "АСВ" | E31: 0 | F31: 0 | G31: 144.386 | H31: 153.426 | I31: 159.041 | J31: 67.7 | K31: 73.7
D32: Обязательства, связанные с активами, предназначенными для продажи | E32: 0 | F32: 0 | G32: 8.502 | H32: 6.06 | I32: 19.775 | J32: 0.3 | K32: 7.6
D33: Текущие налоговые обязательства | E33: 0.089 | F33: 0.039 | G33: 0.224 | H33: 0.531 | I33: 0.894 | J33: 0.9 | K33: 1
D34: Отложенные налоговые обязательства | E34: 1.631 | F34: 0.135 | G34: 0.613 | H34: 1.095 | I34: 1.093 | J34: 6.1 | K34: 1.7
D35: Прочие обязательства | E35: 6.918 | F35: 8.738 | G35: 8.377 | H35: 8.528 | I35: 30.579 | J35: 115.6 | K35: 73.8
D36: Субординированная задолженность | E36: 35.346 | F36: 34.173 | G36: 35.821 | H36: 34.514 | I36: 36.448 | J36: 67.5 | K36: 138.4
D37: Итого обязательства | E37: =SUM(E26:E36) -> 740.479 | F37: =SUM(F26:F36) -> 812.526 | G37: =SUM(G26:G36) -> 897.129 | H37: =SUM(H26:H36) -> 1104.038 | I37: =SUM(I26:I36) -> 1412.584 | J37: =SUM(J26:J36) -> 1941.5 | K37: =SUM(K26:K36) -> 1315.4
D38: Собственные средства
D39: Уставный капитал | E39: 18.313 | F39: 20.476 | G39: 29.651 | H39: 29.651 | I39: 29.651 | J39: 29.7 | K39: 29.7
D40: Эмиссионный доход | E40: 34.09 | F40: 53.624 | G40: 146.449 | H40: 146.449 | I40: 146.449 | J40: 146.4 | K40: 146.4
D41: Собственные средства, выкупленные у акционеров | H41: 0 | I41: -0.0037 | J41: 0 | K41: 0
D42: Фонд переоценки финансовых активов, имеющихся в наличии для продажи | E42: 0.064 | F42: 0.105 | G42: 0.142 | H42: 1.615 | I42: 1.048 | J42: -4.8 | K42: -0.9
D43: Фонд переоценки основных средств | E43: 3.882 | F43: 3.882 | G43: 3.882 | H43: 6.238 | I43: 6.08 | J43: 5.8 | K43: 6.7
D44: Фонд накопленных курсовых разниц | E44: -0.039 | F44: 0.013 | G44: -0.528 | H44: -0.011 | I44: -0.022 | J44: -0.1 | K44: 0.1
...

Sheet Ф_808_2023-2017
A1: Номер строки | B1: Наименование инструмента (показателя) | C1: 2017 | D1: 2018 | E1: 2019 | F1: 2020 | G1: 2021 | H1: 2022 | I1: 2023 | J1: 2024
A2: Источники базового капитала | B2: Источники базового капитала
A3: 1 | B3: Уставный капитал и эмиссионный доход, всего, в том числе сформированный: | C3: 48011741 | D3: 48011741 | E3: 48011741 | F3: 48011741 | G3: 48011741 | H3: 48011741 | I3: 48011741 | J3: 48011741
A4: 1.1 | B4: обыкновенными акциями (долями) | C4: 48011741 | D4: 48011741 | E4: 48011741 | F4: 48011741 | G4: 48011741 | H4: 48011741 | I4: 48011741 | J4: 48011741
A5: 1.2 | B5: привилегированными акциями | C5: 0 | D5: 0 | E5: 0 | F5: 0 | G5: 0 | H5: 0 | I5: 0 | J5: 0
A6: 2 | B6: Нераспределенная прибыль (убыток): | C6: 8346702 | D6: 8743061 | E6: 17195208 | F6: 17152868 | G6: 16934996 | H6: 21228177 | I6: 23797022 | J6: 44867500
A7: 2.1 | B7: прошлых лет | C7: 411512 | D7: 588794 | E7: 6002640 | F7: 16107897 | G7: 13266615 | H7: 17355948 | I7: 18975773 | J7: 44867500
A8: 2.2 | B8: отчетного года | C8: 7935190 | D8: 8154267 | E8: 11192568 | F8: 1044971 | G8: 3668381 | H8: 3872229 | I8: 4821249 | J8: 0
A9: 3 | B9: Резервный фонд | C9: 64084 | D9: 109078 | E9: 207894 | F9: 520535 | G9: 738407 | H9: 1053596 | I9: 1131454 | J9: 1451972
A10: 4 | B10: Доли уставного капитала, подлежащие поэтапному исключению из расчета собственных средств (капитала) | C10: 0 | D10: 0
A11: 5 | B11: Инструменты базового капитала дочерних организаций, принадлежащие третьим сторонам | C11: 0 | D11: 95207
A12: 6 | B12: Источники базового капитала, итого (строка 1 +/– строка 2 + строка 3 – строка 4 + строка 5) | C12: 56422527 | D12: 56959087 | E12: 65414843 | F12: 65685144 | G12: 65685144 | H12: 70293514 | I12: 72940217 | J12: 94331213
A13: Показатели, уменьшающие источники базового капитала | B13: Показатели, уменьшающие источники базового капитала
A14: 7 | B14: Корректировка стоимости финансового инструмента | C14: 0 | D14: 0 | E14: 0 | F14: 0 | G14: 0 | H14: 0 | I14: 0 | J14: 0
A15: 8 | B15: Деловая репутация (гудвил) за вычетом отложенных налоговых обязательств | C15: 0 | D15: 0 | E15: 0 | F15: 0 | G15: 0 | H15: 0 | I15: 0 | J15: 0
A16: 9 | B16: Нематериальные активы (кроме деловой репутации и сумм прав по обслуживанию ипотечных кредитов) за вычетом отложенных налоговых обязательств | C16: 315083 | D16: 747255 | E16: 1783192 | F16: 3037328 | G16: 4409785 | H16: 6973458 | I16: 8737457 | J16: 10774027
A17: 10 | B17: Отложенные налоговые активы, зависящие от будущей прибыли | C17: 85194 | D17: 264330 | E17: 708714 | F17: 883074 | G17: 921846 | H17: 1997406 | I17: 0 | J17: 0
A18: 11 | B18: Резервы хеджирования денежных потоков | C18: 0 | D18: 0 | E18: 0 | F18: 0 | G18: 0 | H18: 0 | I18: 0 | J18: 0
A19: 12 | B19: Недосозданные резервы на возможные потери | C19: 0 | D19: 0 | E19: 0 | F19: 367065 | G19: 367065 | H19: 367065 | I19: 367065 | J19: 367065
A20: 13 | B20: Доход от сделок секьюритизации | C20: 0 | D20: 0
A21: 14 | B21: Доходы и расходы, связанные с изменением кредитного риска по обязательствам, оцениваемым по справедливой стоимости | C21: 0 | D21: 0
A22: 15 | B22: Активы пенсионного плана с установленными выплатами | C22: 0 | D22: 0
A23: 16 | B23: Вложения в собственные акции (доли) | C23: 0 | D23: 378281 | E23: 377330 | F23: 397695
A24: 17 | B24: Встречные вложения кредитной организации и финансовой организации в инструменты базового капитала | C24: 0 | D24: 0 | E24: 6180 | F24: 6180
A25: 18 | B25: Несущественные вложения в инструменты базового капитала финансовых организаций | C25: 0 | D25: 0 | E25: 0 | F25: 0
A26: 19 | B26: Существенные вложения в инструменты базового капитала финансовых организаций | C26: 0 | D26: 0 | E26: 0 | F26: 0
A27: 20 | B27: Права по обслуживанию ипотечных кредитов | C27: 0 | D27: 0
A28: 21 | B28: Отложенные налоговые активы, не зависящие от будущей прибыли | C28: 0 | D28: 0 | E28: 0 | F28: 0 | G28: 0 | H28: 0 | I28: 0 | J28: 0
A29: 22 | B29: Совокупная сумма существенных вложений и отложенных налоговых активов в части, превышающей 15 процентов от величины базового капитала, всего, в том числе: | C29: 0 | D29: 0 | E29: 0 | F29: 0
A30: 23 | B30: существенные вложения в инструменты базового капитала финансовых организаций | C30: 0 | D30: 0 | E30: 0 | F30: 0
A31: 24 | B31: права по обслуживанию ипотечных кредитов | C31: 0 | D31: 0
A32: 25 | B32: отложенные налоговые активы, не зависящие от будущей прибыли | C32: 0 | D32: 0 | F32: 0 | I32: 0 | J32: 0
A33: 26 | B33: Иные показатели, уменьшающие источники базового капитала, установленные Банком России | C33: 299849 | D33: 224198 | E33: 224198 | F33: 224198 | G33: 224198 | H33: 224198 | I33: 224198 | J33: 224198
A34: 27 | B34: Отрицательная величина добавочного капитала | C34: 183731 | D34: 0 | E34: 0 | F34: 0 | G34: 0 | H34: 0 | I34: 0 | J34: 0
A35: 28 | B35: Показатели, уменьшающие источники базового капитала, итого (сумма строк 7–22, 26 и 27) | C35: 883857 | D35: 1614064 | E35: 3099614 | F35: 4915540 | G35: 6339559 | H35: 9981379 | I35: 9746337 | J35: 11755919
A36: 29 | B36: Базовый капитал, итого (строка 6 – строка 28) | C36: 55538670 | D36: 55345023 | E36: 62315229 | F36: 60769604 | G36: 59345585 | H36: 60312135 | I36: 63193880 | J36: 82575294
A37: Источники добавочного капитала | B37: Источники добавочного капитала
A38: 30 | B38: Инструменты добавочного капитала и эмиссионный доход, всего, в том числе: | C38: 0 | D38: 0 | E38: 0 | F38: 0 | G38: 0 | H38: 0 | I38: 0 | J38: 0
A39: 31 | B39: классифицируемые как капитал | C39: 0 | D39: 0 | E39: 0 | F39: 0 | G39: 0 | H39: 0 | I39: 0 | J39: 0
A40: 32 | B40: классифицируемые как обязательства | C40: 0 | D40: 0 | E40: 0 | F40: 0 | G40: 0 | H40: 0 | I40: 0 | J40: 0
...

Sheet Ф_808_2016-2015
A1: Номер строки | B1: Наименование инструмента (показателя) | C1: 2015 | D1: 2016
A2: Источники базового капитала | B2: Источники базового капитала
A3: 1 | B3: Уставный капитал и эмиссионный доход, всего, в том числе, сформированный: | C3: 38011741 | D3: 38011741
A4: 1.1 | B4: обыкновенными акциями (долями) | C4: 38011741 | D4: 38011741
A5: 1.2 | B5: привилегированными акциями | C5: 0 | D5: 0
A6: 2 | B6: Нераспределенная прибыль (убыток): | C6: -3558085 | D6: 4715067
A7: 2.1 | B7: прошлых лет | C7: 5976703 | D7: 805695
A8: 2.2 | B8: отчетного года | C8: -9534788 | D8: 3909372
A9: 3 | B9: Резервный фонд | C9: 2401789 | D9: 0
A10: 4 | B10: Доли уставного капитала, подлежащие поэтапному исключению из расчета собственных средств (капитала)
A11: 5 | B11: Инструменты базового капитала дочерних организаций, принадлежащие третьим сторонам
A12: 6 | B12: Источники базового капитала, итого: (строка 1 +/– строка 2 + строка 3 - строка 4 + строка 5) | C12: 36855445 | D12: 42726808
A13: Показатели, уменьшающие источники базового капитала | B13: Показатели, уменьшающие источники базового капитала
A14: 7 | B14: Корректировка торгового портфеля
A15: 8 | B15: Деловая репутация (Гудвил) за вычетом отложенных налоговых обязательств | C15: 0 | D15: 0
A16: 9 | B16: Нематериальные активы (кроме деловой репутации и сумм прав по обслуживанию ипотечных кредитов) за вычетом отложенных налоговых обязательств | C16: 10518 | D16: 156300
A17: 10 | B17: Отложенные налоговые активы, зависящие от будущей прибыли | C17: 175672 | D17: 0
A18: 11 | B18: Резервы хеджирования денежных потоков
A19: 12 | B19: Недосозданные резервы на возможные потери | C19: 0 | D19: 0
A20: 13 | B20: Доход от сделок секьюритизации
A21: 14 | B21: Доходы и расходы, связанные с изменением кредитного риска по обязательствам, оцениваемым по справедливой стоимости
A22: 15 | B22: Активы пенсионного плана с установленными выплатами
A23: 16 | B23: Вложения в собственные акции (доли) | C23: 0 | D23: 0
A24: 17 | B24: Взаимное перекрестное владение акциями (долями)
A25: 18 | B25: Несущественные вложения в инструменты базового капитала финансовых организаций | C25: 0 | D25: 0
A26: 19 | B26: Существенные вложения в инструменты базового капитала финансовых организаций | C26: 0 | D26: 0
A27: 20 | B27: Права по обслуживанию ипотечных кредитов
A28: 21 | B28: Отложенные налоговые активы, не зависящие от будущей прибыли | C28: 0 | D28: 0
A29: 22 | B29: Совокупная сумма существенных вложений и отложенных налоговых активов в части, превышающей 15 процентов от величины базового капитала, всего, в том числе: | C29: 0 | D29: 0
A30: 23 | B30: существенные вложения в инструменты базового капитала финансовых организаций | C30: 0 | D30: 0
A31: 24 | B31: права по обслуживанию ипотечных кредитов
A32: 25 | B32: отложенные налоговые активы, не зависящие от будущей прибыли | C32: 0 | D32: 0
A33: 26 | B33: Иные показатели, уменьшающие источники базового капитала, установленные Банком России, всего, в том числе: | C33: 190094 | D33: 285141
A34: 26.1 | B34: показатели, подлежащие поэтапному исключению из расчета собственных средств (капитала) | C34: 0 | D34: 0
A35: 27 | B35: Отрицательная величина добавочного капитала | C35: 895002 | D35: 655430
A36: 28 | B36: Показатели, уменьшающие источники базового капитала, итого: (сумма строк с 7 по 22 и строк 26 и 27) | C36: 1271286 | D36: 1096871
A37: 29 | B37: Базовый капитал, итого: (строка 6 – строка 28) | C37: 35584159 | D37: 41629937
A38: Источники добавочного капитала | B38: Источники добавочного капитала
A39: 30 | B39: Инструменты добавочного капитала и эмиссионный доход, всего, в том числе: | C39: 0 | D39: 0
A40: 31 | B40: классифицируемые как капитал | C40: 0 | D40: 0
...

Sheet Ф_135_2017-2015
A1: Краткое наименование норматива | B1: 2017 | C1: 2016 | D1: 2015
A2: Н1.1 | B2: 0.10533 | C2: 0.0771 | D2: 0.0698
A3: Н1.2 | B3: 0.10533 | C3: 0.0771 | D3: 0.0698
A4: Н1.0 | B4: 0.14717 | C4: 0.1336 | D4: 0.1173
A5: Н1.3
A6: Н2 | B6: 2.42094 | C6: 1.7318 | D6: 0.5493
A7: Н3 | B7: 3.30786 | C7: 4.4735 | D7: 0.8269
A8: Н4 | B8: 0.32521 | C8: 0.4237 | D8: 0.8606
A9: Н7 | B9: 1.52423 | C9: 2.0471 | D9: 2.7521
A10: Н9.1 | B10: 0.34012 | C10: 0.1403 | D10: 0.1984
A11: Н10.1 | B11: 0.00216 | C11: 0.0043 | D11: 0.0059
A12: Н12 | B12: 0.14377 | C12: 0.2277 | D12: 0.1018
A13: Н15
A14: Н15.1
A15: Н16
A16: Н16.1
A17: Н16.2
A18: Н18

Sheet Ф_135_2024-2018
A1: Краткое наименование норматива | B1: 2024 | C1: 2023 | D1: 2021 | E1: 2020 | F1: 2019 | G1: 2018
A2: Н1.1 | B2: 0.10932 | C2: 0.09181 | D2: 0.09415 | E2: 0.11613 | F2: 0.11928 | G2: 0.10917
A3: Н1.2 | B3: 0.10932 | C3: 0.09181 | D3: 0.09415 | E3: 0.11613 | F3: 0.11928 | G3: 0.10917
A4: Н1.0 | B4: 0.13298 | C4: 0.14049 | D4: 0.12059 | E4: 0.14334 | F4: 0.15113 | G4: 0.15113
A5: Н1.3
A6: Н1.4 | D6: 0.07781 | E6: 0.08792 | F6: 0.0981 | G6: 0.10551
A7: Н2 | B7: 0.94739 | C7: 1.0833 | D7: 0.47719 | E7: 0.83566 | F7: 1.21316 | G7: 0.73041
A8: Н3 | B8: 1.58313 | C8: 1.42807 | D8: 2.19447 | E8: 0.33194 | F8: 6.48096 | G8: 2.10697
A9: Н4 | B9: 0.46558 | C9: 0.41274 | D9: 0.40717 | E9: 0.31678 | F9: 0.29083 | G9: 0.33024
A10: Н7 | D10: 2.71888 | E10: 2.08775 | F10: 1.96346 | G10: 1.68332
A11: Н12 | D11: 0.15696 | E11: 0.15731 | F11: 0.15225 | G11: 0.14754
A12: Н15
A13: Н15.1
A14: Н16
A15: Н16.1
A16: Н16.2
A17: Н18 | D17: 0 | E17: 0 | F17: 0
A18: Н29

Sheet Ф_123_2021
A1: Номер строки | B1: Наименование показателя | C1: 2021
A2: 000 | B2: Собственные средства (капитал), итого, в том числе: | C2: 76372718
A3: 100 | B3: Источники базового капитала: | C3: 65318079
A4: 100.1 | B4: Уставный капитал кредитной организации: | C4: 48011741
A5: 100.1.1 | B5: сформированный обыкновенными акциями | C5: 48011741
A6: 100.1.2 | B6: сформированный привилегированными акциями, в том числе: | C6: 0
A7: 100.1.2.1 | B7: выпущенными до 1 марта 2013 года | C7: 0
A8: 100.1.3 | B8: сформированный долями | C8: 0
A9: 100.2 | B9: Эмиссионный доход: | C9: 0
A10: 100.2.1 | B10: кредитной организации в организационно-правовой форме акционерного общества, всего, в том числе: | C10: 0
A11: 100.2.1.1 | B11: сформированный при размещении обыкновенных акций | C11: 0
A12: 100.2.1.2 | B12: сформированный при размещении привилегированных акций, в том числе: | C12: 0
A13: 100.2.1.2.1 | B13: выпущенных до 1 марта 2013 года | C13: 0
... A195: 203 | B195: Дополнительный капитал, итого | C195: 16743739

Sheet Ф_123_2020
A1: Номер строки | B1: Наименование показателя | C1: 2020
A2: 000 | B2: Собственные средства (капитал), итого, в том числе: | C2: 75168165
A3: 100 | B3: Источники базового капитала: | C3: 66788831
A4: 100.1 | B4: Уставный капитал кредитной организации: | C4: 48011741
A5: 100.1.1 | B5: сформированный обыкновенными акциями | C5: 48011741
A6: 100.1.2 | B6: сформированный привилегированными акциями, в том числе: | C6: 0
A7: 100.1.2.1 | B7: выпущенными до 1 марта 2013 года | C7: 0
A8: 100.1.3 | B8: сформированный долями | C8: 0
A9: 100.2 | B9: Эмиссионный доход: | C9: 0
A10: 100.2.1 | B10: кредитной организации в организационно-правовой форме акционерного общества, всего, в том числе: | C10: 0
A11: 100.2.1.1 | B11: сформированный при размещении обыкновенных акций | C11: 0
A12: 100.2.1.2 | B12: сформированный при размещении привилегированных акций, в том числе: | C12: 0
A13: 100.2.1.2.1 | B13: выпущенных до 1 марта 2013 года | C13: 0
... A164: 203 | B164: Дополнительный капитал, итого | C164: 14267208

Sheet Ф_123_2019
A1: Номер строки | B1: Наименование показателя | C1: 2019
A2: 000 | B2: Собственные средства (капитал), итого, в том числе: | C2: 78209997
A3: 100 | B3: Источники базового капитала: | C3: 65414843
A4: 100.1 | B4: Уставный капитал кредитной организации: | C4: 48011741
A5: 100.1.1 | B5: сформированный обыкновенными акциями | C5: 48011741
A6: 100.1.2 | B6: сформированный привилегированными акциями, в том числе: | C6: 0
A7: 100.1.2.1 | B7: выпущенными до 1 марта 2013 года | C7: 0
A8: 100.1.3 | B8: сформированный долями | C8: 0
A9: 100.2 | B9: Эмиссионный доход: | C9: 0
A10: 100.2.1 | B10: кредитной организации в организационно-правовой форме акционерного общества, всего, в том числе: | C10: 0
A11: 100.2.1.1 | B11: сформированный при размещении обыкновенных акций | C11: 0
A12: 100.2.1.2 | B12: сформированный при размещении привилегированных акций, в том числе: | C12: 0
A13: 100.2.1.2.1 | B13: выпущенных до 1 марта 2013 года | C13: 0
... A164: 203 | B164: Дополнительный капитал, итого | C164: 16353400

Sheet Ф_123_2018
A1: Номер строки | B1: Наименование показателя | C1: 2018
A2: 000 | B2: Собственные средства (капитал), итого, в том числе: | C2: 79008228
A3: 100 | B3: Источники базового капитала: | C3: 58419021
A4: 100.1 | B4: Уставный капитал кредитной организации: | C4: 48011741
A5: 100.1.1 | B5: сформированный обыкновенными акциями | C5: 48011741
A6: 100.1.2 | B6: сформированный привилегированными акциями | C6: 0
A7: 100.1.3 | B7: сформированный долями | C7: 0
A8: 100.2 | B8: Эмиссионный доход: | C8: 0
A9: 100.2.1 | B9: кредитной организации в организационно-правовой форме акционерного общества, всего, в том числе: | C9: 0
A10: 100.2.1.1 | B10: сформированный при размещении обыкновенных акций | C10: 0
A11: 100.2.1.2 | B11: сформированный при размещении привилегированных акций | C11: 0
A12: 100.2.2 | B12: кредитной организации в организационно-правовой форме общества с ограниченной ответственностью | C12: 0
A13: 100.3 | B13: Часть резервного фонда кредитной организации, сформированная за счет прибыли предшествующих лет | C13: 72364
... A101: 104.6 | B101: Средства, поступившие в оплату акций кредитной организации, включаемых в состав добавочного капитала, в случае, если основное или дочернее общество кредитной организации или любое дочернее общество основного общества кредитной организации предоставило владельцу акций (долей) обязательство, связанное с владением акциями (долями) кредитной организации | C101: 0
A102: 104.7 | B102: Показатели, определенные в соответствии с пунктом 2 приложения к Положению Банка России № 395-П, всего, в том числе:
A103: 104.7.1 | B103: нематериальные активы
A104: 104.7.2 | B104: собственные акции (доли) акционеров (участников), приобретенные (выкупленные) кредитной организацией у акционеров (участников)
A105: 104.7.3 | B105: вложения кредитной организации в акции (доли) дочерних и зависимых финансовых организаций и уставный капитал кредитных организаций - резидентов
A106: 104.7.4 | B106: уставный капитал (его часть) и иные источники собственных средств (эмиссионный доход, прибыль, резервный фонд) (их часть), для формирования которых инвесторами (акционерами, участниками и другими лицами, участвующими в формировании источников собственных средств кредитной организации) использованы ненадлежащие активы
A107: 104.7.5 | B107: отрицательная величина дополнительного капитала
A108: 105 | B108: Добавочный капитал, итого | C108: 0
A109: 106 | B109: Основной капитал, итого | C109: 57073901
A110: 200 | B110: Источники дополнительного капитала: | C110: 21953077
A111: 200.1 | B111: Уставный капитал кредитной организации в организационно-правовой форме акционерного общества, сформированный в результате выпуска и размещения привилегированных акций, всего, в том числе: | C111: 0
A112: 200.1.1 | B112: уставный капитал кредитной организации в организационно-правовой форме акционерного общества, сформированный в результате выпуска и размещения привилегированных акций, проведенных до 1 марта 2013 года | C112: 0
A113: 200.1.2 | B113: уставный капитал кредитной организации в организационно-правовой форме акционерного общества, сформированный в результате выпуска и размещения привилегированных акций, проведенных после 1 марта 2013 года | C113: 0
A114: 200.2 | B114: Часть уставного капитала кредитной организации, сформированного за счет капитализации прироста стоимости основных средств при переоценке до выбытия основных средств | C114: 3655
A115: 200.3 | B115: Эмиссионный доход кредитной организации в организационно-правовой форме акционерного общества | C115: 0
A116: 200.4 | B116: Резервный фонд кредитной организации в части, сформированной за счет отчислений из прибыли текущего года | C116: 0
A117: 200.5 | B117: Прибыль текущего года (ее часть), не подтвержденная аудиторской организацией, всего, в том числе: | C117: 5904976
A118: 200.5.1 | B118: величина резерва (резервов), фактически недосозданного кредитной организацией по сравнению с величиной, требуемой в соответствии с нормативными актами Банка России, всего, в том числе в соответствии: | C118: 0
A119: 200.5.1.1 | B119: с Положением Банка России № 590-П | C119: 0
... A156: 201.6 | B156: Промежуточный итог | C156: 79008228
A157: 201.7 | B157: Показатели, определенные в соответствии с пунктами 3-5 приложения к Положению Банка России № 395-П, всего, в том числе:
A158: 201.7.1 | B158: источники (часть источников) дополнительного капитала (уставного капитала, нераспределенной прибыли, резервного фонда, субординированного кредита), для формирования которых инвесторами использованы ненадлежащие активы
A159: 201.7.2 | B159: просроченная дебиторская задолженность длительностью свыше 30 календарных дней, учитываемая на балансовых счетах
A160: 201.7.3 | B160: субординированные кредиты (депозиты, займы, облигационные займы), в том числе субординированные займы с дополнительными условиями, предоставленные кредитным организациям - резидентам
A161: 201.7.4 | B161: величина превышения совокупной суммы кредитов, банковских гарантий и поручительств, предоставленных кредитной организацией участникам (акционерам) и инсайдерам, над ее максимальным размером, предусмотренным федеральными законами и нормативными актами Банка России
A162: 201.7.5 | B162: вложения, превышающие сумму источников основного и дополнительного капитала, в приобретение основных средств (в том числе земли), сооружение (строительство) и создание (изготовление) основных средств, в недвижимость, временно неиспользуемую в основной деятельности, в сооружение (строительство) объектов недвижимости, временно неиспользуемой в основной деятельности, долгосрочные активы, предназначенные для продажи, а также запасы (за исключением изданий)
A163: 201.7.5.1 | B163: справочно: совокупная сумма вложений в активы, указанные в подпункте 5.2 пункта 5 приложения к Положению Банка России № 395-П
...

Sheet Ф_123_2017
A1: Номер строки | B1: Наименование показателя | C1: 2017
A2: 000 | B2: Собственные средства (капитал), итого, в том числе: | C2: 78930785
A3: 100 | B3: Источники базового капитала: | C3: 57403326
A4: 100.1 | B4: Уставный капитал кредитной организации: | C4: 48011741
A5: 100.1.1 | B5: сформированный обыкновенными акциями | C5: 48011741
